Workbook

Sheet Guide
A1: E04 Authentic and Secure Assessment in AI-Rich Computing Education
A2: Evidence Screening Log | Evidence Screening Lead: Prajwal Acharaya | Version 1, 23/09/2026
A4: HOW TO USE | B4: This is for group memeber to ad. add/ edit this excel file .
A5: 1 | B5: Add every record you find to the Evidence Log tab, one row each, including duplicates (mark them Duplicate = Yes).
A6: 2 | B6: Screen title/abstract first (Include / Exclude / Maybe). Only Include or Maybe records go to full-text screening.
A7: 3 | B7: After reading the full text, set Full-text Screen to Include or Exclude. Leave it blank if the full text is not yet retrieved.
A8: 4 | B8: If excluded, pick one reason code from the list below. Final Decision fills in automatically (grey columns are formulas, do not type in them).
A9: 5 | B9: The PRISMA Counts tab updates itself and gives the numbers for the PRISMA flow diagram.
A11: INCLUSION CRITERIA (draft, confirm with group)
A12: IC1 | B12: Higher education or tertiary context
A13: IC2 | B13: Focus on assessment design, assessment validity or academic integrity
A14: IC3 | B14: Involves generative AI / LLMs (or AI in assessment more broadly)
A15: IC4 | B15: Peer-reviewed journal article, conference paper, or formal framework paper
A16: IC5 | B16: Published 2022 to 2026, written in English
A18: EXCLUSION REASON CODES
A19: E1 | B19: Not higher education
A20: E2 | B20: Not about assessment or academic integrity
A21: E3 | B21: No AI / GenAI context
A22: E4 | B22: Not peer-reviewed (forum post, blog, opinion without review)
A23: E5 | B23: Outside date range (before 2022)
A24: E6 | B24: Not in English
A25: E7 | B25: Full text not available after retrieval attempt
A27: THEME CODES
A28: T1 | B28: Academic integrity and limits of AI detection
A29: T2 | B29: Assessment redesign: authentic, process-based, multi-stage
A30: T3 | B30: Oral / viva verification of understanding
A31: T4 | B31: AI-use frameworks, scales and declaration
A32: T5 | B32: Computing / programming-specific evidence
A33: T6 | B33: AI literacy, staff development and institutional policy
A35: COLOUR KEY
A36: Green | B36: Include
A37: Red | B37: Exclude
A38: Yellow | B38: Pending (full text still needed) | D38: This is automated
A39: Grey | B39: Duplicate / formula column
A42: 16/10/2026 relevance screening update
A43: Decision method | B43: Relevant records selected from supplied titles and summaries. Final Decision records relevance selection; Full-text Screen remains separate.
A44: Scope | B44: Tertiary AI/GenAI assessment, validity, integrity and supporting learning/context evidence. Programming-intensive engineering retained as adjacent evidence.
A45: Evidence roles | B45: Core assessment, supporting/contextual and background-only records are distinguished in AX. Inclusion does not establish study quality or effectiveness.
A47: Strict scope revision
A48: Main synthesis | B48: Higher-education Computing/IT assessment design, security, integrity or verification of understanding. Include direct empirical, design, technical and disciplinary framework evidence; identify study type.
...

Sheet Evidence Log
A1: Record ID | B1: Date Logged | C1: Source / How Found | D1: File Name / Paper Title | E1: Author(s) | F1: Year | G1: Title | H1: Journal / Venue | I1: DOI / Link | J1: Publication Type | K1: Study Design / Method | L1: Context | M1: Duplicate? | N1: Duplicate of | O1: Title/Abstract Screen | P1: Full-text Screen | Q1: Exclusion Code | R1: Final Decision | S1: Relevance to E04 | T1: Theme Codes | U1: Key Finding (own words) | V1: Screener | W1: Notes / Next Action | AD1: Older evidence flag | AE1: Missing information | AF1: Repeated DOI / link | AG1: Pending review | AI1: Screening totals | AJ1: Count | AL1: Pending record IDs | AO1: Assessment category / focus | AP1: Assessment strategy | AQ1: GenAI context | AR1: Relevance rationale / discipline | AS1: Limitations | AT1: Source inclusion recommendation | AU1: RQ mapping (source interpretation) | AV1: Project benefits / proposed applications | AW1: Source reference | AX1: Evidence role | AY1: Decision basis | AZ1: Relevance rationale | BA1: Full-text verification
A2: R01 | B2: 23/09/2026 | C2: Group upload (shared folder) | D2: Redefining student assessment in AI-infused learning environments: a systematic review of challenges and strategies for academic integrity Original file: Redefining_student_assessment_in_AI-infused_learni.pdf | E2: Ncube, Dzvapatsva, Matobobo & Ranga | F2: 2026 | G2: Redefining student assessment in AI-infused learning environments: a systematic review of challenges and strategies for academic integrity | H2: AI and Ethics, 6, Article 68 | I2: https://doi.org/10.1007/s43681-025-00871-w | J2: Journal article | K2: Systematic review (PRISMA), 56 studies, thematic analysis | L2: Higher education, multi-discipline | M2: No | O2: Include | P2: Include | R2: Background | S2: High | T2: T1, T2, T3, T6 | U2: AI detection tools are unreliable, so integrity depends on redesign: oral exams, scaffolded multi-stage tasks, AI disclosure and AI literacy. Recommends vivas as routine, not only for misconduct cases. | V2: PA | W2: Strong anchor source for the 'secure assessment' side. 16/10/2026 relevance decision: Include. Addresses assessment design, verification of understanding, assessment validity or integrity in AI-rich education. Revised strict-scope decision: Background only. Secondary synthesis or broad review; retain to frame or locate primary studies, outside the direct assessment-study synthesis. | AD2: =IF(G2="","",IF(F2="","",IF(AND(F2>=2022,F2<=2024),"Review 2026 applicability",""))) | AE2: =IF(G2="","",IF(OR(E2="",F2="",I2="",V2=""),"Missing author/year/link/screener","")) | AF2: =IF(G2="","",IF(I2="","",IF(COUNTIF($I$2:$I$100,I2)>1,"Check duplicate",""))) | AG2: =IF(G2="","",IF(M2="Yes","Duplicate",IF(OR(R2="",R2="Pending"),"Review pending",""))) | AI2: Records with titles | AJ2: =COUNTA(G2:G100) | AL2: {=_xlfn._xlws.FILTER(A2:A100,AG2:AG100="Review pending","None")} | AX2: Background, outside main synthesis | AY2: Tighter relevance screen of supplied title, context and summary; not a new full-text assessment. | AZ2: Secondary synthesis or broad review; retain to frame or locate primary studies, outside the direct assessment-study synthesis. | BA2: Existing full-text screen recorded; not reverified in this update.
A3: R02 | B3: 23/09/2026 | C3: Group upload (shared folder) | D3: Redefining student assessment in AI-infused learning environments (second copy) Original file: Redefining_student_assessment_in_AI-infused_learni__1_.pdf | E3: Ncube et al. | F3: 2026 | G3: Redefining student assessment in AI-infused learning environments (second copy) | H3: AI and Ethics | I3: https://doi.org/10.1007/s43681-025-00871-w | J3: Journal article | M3: Yes | N3: R01 | O3: N/A | R3: =IF(M3="Yes","Duplicate",IF(O3="Exclude","Exclude",IF(P3="","Pending",P3))) | S3: Low | U3: Identical file to R01. | V3: PA | W3: Removed as duplicate. | AD3: =IF(G3="","",IF(F3="","",IF(AND(F3>=2022,F3<=2024),"Review 2026 applicability",""))) | AE3: =IF(G3="","",IF(OR(E3="",F3="",I3="",V3=""),"Missing author/year/link/screener","")) | AF3: =IF(G3="","",IF(I3="","",IF(COUNTIF($I$2:$I$100,I3)>1,"Check duplicate",""))) | AG3: =IF(G3="","",IF(M3="Yes","Duplicate",IF(OR(R3="",R3="Pending"),"Review pending",""))) | AI3: Main-synthesis Include | AJ3: =COUNTIF(R2:R100,"Include") | AL3: R96
A4: R03 | B4: 23/09/2026 | C4: Group upload (shared folder) | D4: A scoping review on how generative artificial intelligence transforms assessment in higher education Original file: s41239-024-00468-z.pdf | E4: Xia, Weng, Ouyang, Lin & Chiu | F4: 2024 | G4: A scoping review on how generative artificial intelligence transforms assessment in higher education | H4: Int. J. of Educational Technology in Higher Education, 21, Article 40 | I4: https://doi.org/10.1186/s41239-024-00468-z | J4: Journal article | K4: Scoping review (PRISMA-ScR), 32 empirical studies | L4: Higher education, 11 disciplines incl. computer science | M4: No | O4: Include | P4: Include | R4: Background | S4: High | T4: T1, T2, T6 | U4: Maps GenAI impact at student, teacher and institution levels. Integrity is the main student-level concern; teachers need assessment and AI literacy; institutions must rethink assessment policy. | V4: PA | W4: Useful three-level structure for our analysis. 2022-2024 flag: Review applicability to 2026 GenAI during extraction; document specific limitations. 16/10/2026 relevance decision: Include. Addresses assessment design, verification of understanding, assessment validity or integrity in AI-rich education. Revised strict-scope decision: Background only. Secondary synthesis or broad review; retain to frame or locate primary studies, outside the direct assessment-study synthesis. | AD4: =IF(G4="","",IF(F4="","",IF(AND(F4>=2022,F4<=2024),"Review 2026 applicability",""))) | AE4: =IF(G4="","",IF(OR(E4="",F4="",I4="",V4=""),"Missing author/year/link/screener","")) | AF4: =IF(G4="","",IF(I4="","",IF(COUNTIF($I$2:$I$100,I4)>1,"Check duplicate",""))) | AG4: =IF(G4="","",IF(M4="Yes","Duplicate",IF(OR(R4="",R4="Pending"),"Review pending",""))) | AI4: Excluded | AJ4: =COUNTIF(R2:R100,"Exclude") | AL4: R96 | AX4: Background, outside main synthesis | AY4: Tighter relevance screen of supplied title, context and summary; not a new full-text assessment. | AZ4: Secondary synthesis or broad review; retain to frame or locate primary studies, outside the direct assessment-study synthesis. | BA4: Existing full-text screen recorded; not reverified in this update.
A5: R04 | B5: 23/09/2026 | C5: Group upload (shared folder) | D5: Designing assessments in the generative AI era: A tailored assessment framework for ICT tertiary education Original file: Ahangama__2026_.pdf | E5: Ahangama | F5: 2026 | G5: Designing assessments in the generative AI era: A tailored assessment framework for ICT tertiary education | H5: Int. J. of Educational Technology in Higher Education, 23, Article 9 | I5: https://doi.org/10.1186/s41239-026-00582-0 | J5: Journal article | K5: Qualitative document analysis (thematic), framework development | L5: ICT tertiary education, Australia | M5: No | O5: Include | P5: Include | R5: Include | S5: High | T5: T2, T4, T5, T6 | U5: Proposes the GENESIS five-pillar institutional framework and an Assessment Design Matrix linking ICT graduate competencies, strategies and methods for integrity-focused assessment. | V5: PA | W5: Most directly on-topic (ICT + assessment design). 16/10/2026 relevance decision: Include. Addresses assessment design, verification of understanding, assessment validity or integrity in AI-rich education. Revised strict-scope decision: Include in main synthesis. ICT-specific assessment-design framework; retain as conceptual design evidence, not an effectiveness trial. | AD5: =IF(G5="","",IF(F5="","",IF(AND(F5>=2022,F5<=2024),"Review 2026 applicability",""))) | AE5: =IF(G5="","",IF(OR(E5="",F5="",I5="",V5=""),"Missing author/year/link/screener","")) | AF5: =IF(G5="","",IF(I5="","",IF(COUNTIF($I$2:$I$100,I5)>1,"Check duplicate",""))) | AG5: =IF(G5="","",IF(M5="Yes","Duplicate",IF(OR(R5="",R5="Pending"),"Review pending",""))) | AI5: Duplicates | AJ5: =COUNTIF(M2:M100,"Yes") | AL5: R96 | AX5: Main synthesis, design / preliminary evidence | AY5: Tighter relevance screen of supplied title, context and summary; not a new full-text assessment. | AZ5: ICT-specific assessment-design framework; retain as conceptual design evidence, not an effectiveness trial. | BA5: Existing full-text screen recorded; not reverified in this update.
A6: R05 | B6: 23/09/2026 | C6: Group upload (shared folder) | D6: Designing assessments in the generative AI era (second copy) Original file: s41239-026-00582-0.pdf | E6: Ahangama | F6: 2026 | G6: Designing assessments in the generative AI era (second copy) | H6: IJETHE | I6: https://doi.org/10.1186/s41239-026-00582-0 | J6: Journal article | M6: Yes | N6: R04 | O6: N/A | R6: =IF(M6="Yes","Duplicate",IF(O6="Exclude","Exclude",IF(P6="","Pending",P6))) | S6: Low | U6: Identical file to R04. | V6: PA | W6: Removed as duplicate. | AD6: =IF(G6="","",IF(F6="","",IF(AND(F6>=2022,F6<=2024),"Review 2026 applicability",""))) | AE6: =IF(G6="","",IF(OR(E6="",F6="",I6="",V6=""),"Missing author/year/link/screener","")) | AF6: =IF(G6="","",IF(I6="","",IF(COUNTIF($I$2:$I$100,I6)>1,"Check duplicate",""))) | AG6: =IF(G6="","",IF(M6="Yes","Duplicate",IF(OR(R6="",R6="Pending"),"Review pending",""))) | AI6: Pending (incl. blank decision) | AJ6: =COUNTIF(AG2:AG100,"Review pending") | AL6: R96
A7: R06 | B7: 23/09/2026 | C7: Group upload (shared folder) | D7: Designing assessments in the generative AI era (third copy) Original file: s41239-026-00582-0__1_.pdf | E7: Ahangama | F7: 2026 | G7: Designing assessments in the generative AI era (third copy) | H7: IJETHE | I7: https://doi.org/10.1186/s41239-026-00582-0 | J7: Journal article | M7: Yes | N7: R04 | O7: N/A | R7: =IF(M7="Yes","Duplicate",IF(O7="Exclude","Exclude",IF(P7="","Pending",P7))) | S7: Low | U7: Identical file to R04. | V7: PA | W7: Removed as duplicate. | AD7: =IF(G7="","",IF(F7="","",IF(AND(F7>=2022,F7<=2024),"Review 2026 applicability",""))) | AE7: =IF(G7="","",IF(OR(E7="",F7="",I7="",V7=""),"Missing author/year/link/screener","")) | AF7: =IF(G7="","",IF(I7="","",IF(COUNTIF($I$2:$I$100,I7)>1,"Check duplicate",""))) | AG7: =IF(G7="","",IF(M7="Yes","Duplicate",IF(OR(R7="",R7="Pending"),"Review pending",""))) | AI7: Background only | AJ7: =COUNTIF(R2:R100,"Background") | AL7: R96
A8: R07 | B8: 23/09/2026 | C8: Group upload (shared folder) | D8: Assessment in the age of artificial intelligence Original file: Assessment_in_the_age_of_artificial_intelligence.pdf | E8: Swiecki, Khosravi, Chen, Martinez-Maldonado, Lodge, Milligan, Selwyn & Gašević | F8: 2022 | G8: Assessment in the age of artificial intelligence | H8: Computers and Education: Artificial Intelligence, 3, 100075 | I8: https://doi.org/10.1016/j.caeai.2022.100075 | J8: Journal article | K8: Conceptual / critical review | L8: Education (general), Australia | M8: No | O8: Include | P8: Include | R8: Background | S8: Medium | T8: T1, T2, T6 | U8: Argues traditional assessment is onerous, discrete, uniform, inauthentic and antiquated; AI can help but brings risks such as hidden accountability, surveillance and narrower forms of learning. | V8: PA | W8: Pre-ChatGPT; use for background and theory. 2022-2024 flag: Review applicability to 2026 GenAI during extraction; document specific limitations. 16/10/2026 relevance decision: Include. Relevant conceptual, learning-process, AI-literacy or institutional context; use as supporting evidence, not proof of assessment effectiveness. Revised strict-scope decision: Background only. Broad AI, learning, literacy or policy context, or insufficient direct assessment-design evidence in the supplied summary; retain for background only. | AD8: =IF(G8="","",IF(F8="","",IF(AND(F8>=2022,F8<=2024),"Review 2026 applicability",""))) | AF8: =IF(G8="","",IF(I8="","",IF(COUNTIF($I$2:$I$100,I8)>1,"Check duplicate",""))) | AG8: =IF(G8="","",IF(M8="Yes","Duplicate",IF(OR(R8="",R8="Pending"),"Review pending",""))) | AL8: R96 | AX8: Background, outside main synthesis | AY8: Tighter relevance screen of supplied title, context and summary; not a new full-text assessment. | AZ8: Broad AI, learning, literacy or policy context, or insufficient direct assessment-design evidence in the supplied summary; retain for background only. | BA8: Existing full-text screen recorded; not reverified in this update.
A9: R08 | B9: 23/09/2026 | C9: Group upload (shared folder) | D9: Computing education in the era of generative AI Original file: Computing_education_in_the_era_of_GenAI-01.pdf | E9: Denny, Prather, Becker, Finnie-Ansley, Hellas, Leinonen, Luxton-Reilly, Reeves, Santos & Sarsa | F9: 2024 | G9: Computing education in the era of generative AI | H9: Communications of the ACM, 67(2), 56-67 | I9: https://doi.org/10.1145/3624720 | J9: Journal article | K9: Review / position paper drawing on authors' empirical studies | L9: Introductory programming (CS1/CS2) | M9: No | O9: Include | P9: Include | R9: Include | S9: High | T9: T1, T3, T5 | U9: GPT-4 scored close to the top of a CS1 class on real exams, and plagiarism tools miss AI code. Recommends clear AI rules per assessment, secure testing and a stronger focus on process and code-reading skills. | V9: PA | W9: Key computing evidence for why take-home coding tasks are insecure. 2022-2024 flag: Review applicability to 2026 GenAI during extraction; document specific limitations. 16/10/2026 relevance decision: Include. Addresses assessment design, verification of understanding, assessment validity or integrity in AI-rich education. Revised strict-scope decision: Include in main synthesis. Computing-specific assessment vulnerabilities and verification recommendations; retain as review/position evidence. | AD9: =IF(G9="","",IF(F9="","",IF(AND(F9>=2022,F9<=2024),"Review 2026 applicability",""))) | AF9: =IF(G9="","",IF(I9="","",IF(COUNTIF($I$2:$I$100,I9)>1,"Check duplicate",""))) | AG9: =IF(G9="","",IF(M9="Yes","Duplicate",IF(OR(R9="",R9="Pending"),"Review pending",""))) | AL9: R96 | AX9: Main synthesis, assessment evidence | AY9: Tighter relevance screen of supplied title, context and summary; not a new full-text assessment. | AZ9: Computing-specific assessment vulnerabilities and verification recommendations; retain as review/position evidence. | BA9: Existing full-text screen recorded; not reverified in this update.
A10: R09 | B10: 23/09/2026 | C10: Group upload (shared folder) | D10: Incorporating generative AI into software development education Original file: Incorporating_Generative_AI_into_Software_Development_Education.pdf | E10: Petrovska, Clift, Moller & Pearsall | F10: 2024 | G10: Incorporating generative AI into software development education | H10: Proceedings of Computing Education Practice (CEP '24), 37-40 | I10: https://doi.org/10.1145/3633053.3633057 | J10: Conference paper | K10: Surveys (first-year n=12, final-year n=12, industry n=13) plus experimental summative assessment (n=17) | L10: Software engineering degree apprenticeship, UK | M10: No | O10: Include | P10: Include | R10: Include | S10: High | T10: T2, T4, T5 | U10: Assessments that make students critically evaluate ChatGPT output worked well; most students spotted its weaknesses, but some over-relied on it (e.g., did not notice wrong-language code). | V10: PA | W10: Good example of an authentic AI-inclusive computing assessment. 2022-2024 flag: Review applicability to 2026 GenAI during extraction; document specific limitations. 16/10/2026 relevance decision: Include. Addresses assessment design, verification of understanding, assessment validity or integrity in AI-rich education. Revised strict-scope decision: Include in main synthesis. Direct higher-education Computing/IT evidence on assessment design, assessment security, integrity or verification of individual understanding. | AD10: =IF(G10="","",IF(F10="","",IF(AND(F10>=2022,F10<=2024),"Review 2026 applicability",""))) | AF10: =IF(G10="","",IF(I10="","",IF(COUNTIF($I$2:$I$100,I10)>1,"Check duplicate",""))) | AG10: =IF(G10="","",IF(M10="Yes","Duplicate",IF(OR(R10="",R10="Pending"),"Review pending",""))) | AL10: R96 | AX10: Main synthesis, assessment evidence | AY10: Tighter relevance screen of supplied title, context and summary; not a new full-text assessment. | AZ10: Direct higher-education Computing/IT evidence on assessment design, assessment security, integrity or verification of individual understanding. | BA10: Existing full-text screen recorded; not reverified in this update.
A11: R10 | B11: 23/09/2026 | C11: Group upload (shared folder) | D11: The Artificial Intelligence Assessment Scale (AIAS): A framework for ethical integration of generative AI in educational assessment Original file: JUTLP_AI_Assessment_Scale_final.pdf | E11: Perkins, Furze, Roe & MacVaugh | F11: 2024 | G11: The Artificial Intelligence Assessment Scale (AIAS): A framework for ethical integration of generative AI in educational assessment | H11: Journal of University Teaching and Learning Practice, 21(6) | I11: https://doi.org/10.53761/q3azde36 | J11: Journal article | K11: Conceptual framework | L11: Higher education (adaptable to K-12) | M11: No | O11: Include | P11: Include | R11: Background | S11: High | T11: T4, T1 | U11: Five-level scale (No AI to Full AI) so educators state exactly how much GenAI each task allows. Recommends Level 1 tasks be supervised because unsupervised 'no AI' rules cannot be enforced fairly. | V11: PA | W11: Widely used scale; candidate for our AI-use dimension. 2022-2024 flag: Review applicability to 2026 GenAI during extraction; document specific limitations. 16/10/2026 relevance decision: Include. Addresses assessment design, verification of understanding, assessment validity or integrity in AI-rich education. Revised strict-scope decision: Background only. Broad AI, learning, literacy or policy context, or insufficient direct assessment-design evidence in the supplied summary; retain for background only. | AD11: =IF(G11="","",IF(F11="","",IF(AND(F11>=2022,F11<=2024),"Review 2026 applicability",""))) | AF11: =IF(G11="","",IF(I11="","",IF(COUNTIF($I$2:$I$100,I11)>1,"Check duplicate",""))) | AG11: =IF(G11="","",IF(M11="Yes","Duplicate",IF(OR(R11="",R11="Pending"),"Review pending",""))) | AL11: R96 | AX11: Background, outside main synthesis | AY11: Tighter relevance screen of supplied title, context and summary; not a new full-text assessment. | AZ11: Broad AI, learning, literacy or policy context, or insufficient direct assessment-design evidence in the supplied summary; retain for background only. | BA11: Existing full-text screen recorded; not reverified in this update.
A12: R11 | B12: 23/09/2026 | C12: Group upload (shared folder) | D12: Coauthorship integrity: Reconceptualising assessment validity for the age of generative artificial intelligence Original file: Ebrahimzadeh_-_Comp___Edu__2026_.pdf | E12: Ebrahimzadeh, Shibani & Buckingham Shum | F12: 2026 | G12: Coauthorship integrity: Reconceptualising assessment validity for the age of generative artificial intelligence | H12: Computers and Education: Artificial Intelligence, 10, 100609 | I12: https://doi.org/10.1016/j.caeai.2026.100609 | J12: Journal article | K12: Conceptual + prototype (AI Viva) with expert evaluation | L12: Higher education writing, Australia | M12: No | O12: Include | P12: Include | R12: Background | S12: High | T12: T1, T3 | U12: Proposes 'coauthorship integrity': students must understand what they submit, even if AI helped. Tests an AI Viva chatbot that asks comprehension questions to check this at scale. | V12: PA | W12: Supports scalable oral-style verification. 16/10/2026 relevance decision: Include. Addresses assessment design, verification of understanding, assessment validity or integrity in AI-rich education. Revised strict-scope decision: Background only. Broad AI, learning, literacy or policy context, or insufficient direct assessment-design evidence in the supplied summary; retain for background only. | AD12: =IF(G12="","",IF(F12="","",IF(AND(F12>=2022,F12<=2024),"Review 2026 applicability",""))) | AF12: =IF(G12="","",IF(I12="","",IF(COUNTIF($I$2:$I$100,I12)>1,"Check duplicate",""))) | AG12: =IF(G12="","",IF(M12="Yes","Duplicate",IF(OR(R12="",R12="Pending"),"Review pending",""))) | AL12: R96 | AX12: Background, outside main synthesis | AY12: Tighter relevance screen of supplied title, context and summary; not a new full-text assessment. | AZ12: Broad AI, learning, literacy or policy context, or insufficient direct assessment-design evidence in the supplied summary; retain for background only. | BA12: Existing full-text screen recorded; not reverified in this update.
A13: R12 | B13: 23/09/2026 | C13: Group upload (shared folder) | D13: How university students work on assessment tasks with generative artificial intelligence Original file: How_university_students_work_on_assessment_tasks_with_generative_artificial_intelligence.txt | E13: To be confirmed | F13: 2025 | G13: How university students work on assessment tasks with generative artificial intelligence | H13: Assessment & Evaluation in Higher Education (per DOI) | I13: https://doi.org/10.1080/02602938.2025.2570328 | J13: Journal article | K13: To be confirmed after full-text read | L13: Higher education | M13: No | O13: Include | R13: Background | V13: PA | W13: Only a DOI link was shared. Download full text, then complete this row. 16/10/2026 relevance decision: Include. Relevant conceptual, learning-process, AI-literacy or institutional context; use as supporting evidence, not proof of assessment effectiveness. Revised strict-scope decision: Background only. Broad AI, learning, literacy or policy context, or insufficient direct assessment-design evidence in the supplied summary; retain for background only. | AD13: =IF(G13="","",IF(F13="","",IF(AND(F13>=2022,F13<=2024),"Review 2026 applicability",""))) | AF13: =IF(G13="","",IF(I13="","",IF(COUNTIF($I$2:$I$100,I13)>1,"Check duplicate",""))) | AG13: =IF(G13="","",IF(M13="Yes","Duplicate",IF(OR(R13="",R13="Pending"),"Review pending",""))) | AL13: R96 | AX13: Background, outside main synthesis | AY13: Tighter relevance screen of supplied title, context and summary; not a new full-text assessment. | AZ13: Broad AI, learning, literacy or policy context, or insufficient direct assessment-design evidence in the supplied summary; retain for background only. | BA13: Not independently checked against original full text.
A14: R13 | B14: 23/09/2026 | C14: Group upload (shared folder) | D14: Are report-based assessments and viva examinations effective alternatives to written exams in computing education? Original file: research_discussion.docx | E14: ResearchGate users | F14: 2025 | G14: Are report-based assessments and viva examinations effective alternatives to written exams in computing education? | H14: ResearchGate Q&A forum | I14: https://www.researchgate.net/post/Are_report-based_assessments_and_viva_examinations_effective_alternatives_to_written_exams_in_computing_education | J14: Online discussion | K14: N/A | L14: Computing education | M14: No | O14: Exclude | Q14: E4 | R14: Exclude | S14: Low | V14: PA | W14: Not peer-reviewed. Year approximate. Can be cited only as informal background, not evidence. 16/10/2026 relevance decision: Exclude. Existing exclusion retained; see the original exclusion code and notes. | AD14: =IF(G14="","",IF(F14="","",IF(AND(F14>=2022,F14<=2024),"Review 2026 applicability",""))) | AF14: =IF(G14="","",IF(I14="","",IF(COUNTIF($I$2:$I$100,I14)>1,"Check duplicate",""))) | AG14: =IF(G14="","",IF(M14="Yes","Duplicate",IF(OR(R14="",R14="Pending"),"Review pending",""))) | AL14: R96 | AX14: Excluded (existing decision) | AY14: Existing decision retained; supporting classification added. | AZ14: Existing exclusion retained; see the original exclusion code and notes. | BA14: Not independently checked against original full text.
A15: R14 | B15: 23/09/2026 | C15: Sachin, Papers Key Findings doc | D15: Themes in the declared use of generative artificial intelligence in assessment Original file: Not uploaded | E15: Maguire et al. | F15: 2025 | G15: Themes in the declared use of generative artificial intelligence in assessment | H15: ACM publication (confirm venue) | I15: https://doi.org/10.1145/3702212.3702217 | J15: Conference paper | K15: To be confirmed | L15: Computing / higher education | M15: No | O15: Include | R15: Background | T15: T4 | U15: Per Sachin's summary: looks at how students declare GenAI use in assessment; supports clearly defined, transparent AI-use rules. | V15: PA | W15: Retrieve full text to confirm. 16/10/2026 relevance decision: Include. Relevant conceptual, learning-process, AI-literacy or institutional context; use as supporting evidence, not proof of assessment effectiveness. Revised strict-scope decision: Background only. Broad AI, learning, literacy or policy context, or insufficient direct assessment-design evidence in the supplied summary; retain for background only. | AD15: =IF(G15="","",IF(F15="","",IF(AND(F15>=2022,F15<=2024),"Review 2026 applicability",""))) | AF15: =IF(G15="","",IF(I15="","",IF(COUNTIF($I$2:$I$100,I15)>1,"Check duplicate",""))) | AG15: =IF(G15="","",IF(M15="Yes","Duplicate",IF(OR(R15="",R15="Pending"),"Review pending",""))) | AL15: R96 | AX15: Background, outside main synthesis | AY15: Tighter relevance screen of supplied title, context and summary; not a new full-text assessment. | AZ15: Broad AI, learning, literacy or policy context, or insufficient direct assessment-design evidence in the supplied summary; retain for background only. | BA15: Not independently checked against original full text.
A16: R15 | B16: 23/09/2026 | C16: Sachin, Papers Key Findings doc | D16: The summative assessment of generative AI usage within academic writing in a computing foundation year Original file: Not uploaded | E16: Prickett & Foster | F16: 2026 | G16: The summative assessment of generative AI usage within academic writing in a computing foundation year | H16: ACM publication (confirm venue) | I16: https://doi.org/10.1145/3772338.3772347 | J16: Conference paper | K16: To be confirmed | L16: Computing foundation year | M16: No | O16: Include | R16: Include | T16: T2, T4, T5 | U16: Per Sachin's summary: a computing assessment where students use and critically evaluate GenAI while still showing their own understanding. | V16: PA | W16: Retrieve full text to confirm. 16/10/2026 relevance decision: Include. Addresses assessment design, verification of understanding, assessment validity or integrity in AI-rich education. Revised strict-scope decision: Include in main synthesis. Computing-foundation-year assessment of GenAI use; relevance established from supplied title, bibliographic and full-text details still require verification. | AD16: =IF(G16="","",IF(F16="","",IF(AND(F16>=2022,F16<=2024),"Review 2026 applicability",""))) | AF16: =IF(G16="","",IF(I16="","",IF(COUNTIF($I$2:$I$100,I16)>1,"Check duplicate",""))) | AG16: =IF(G16="","",IF(M16="Yes","Duplicate",IF(OR(R16="",R16="Pending"),"Review pending",""))) | AL16: R96 | AX16: Main synthesis, assessment evidence | AY16: Tighter relevance screen of supplied title, context and summary; not a new full-text assessment. | AZ16: Computing-foundation-year assessment of GenAI use; relevance established from supplied title, bibliographic and full-text details still require verification. | BA16: Not independently checked against original full text.
A17: R16 | B17: 14/10/2026 | C17: User paper list, item 1 | D17: Beyond Detection: Redesigning Authentic Assessment in an AI-Mediated World Original file: Relevant Papers 2022-26(1).docx | F17: 2025 | G17: Beyond Detection: Redesigning Authentic Assessment in an AI-Mediated World | I17: https://doi.org/10.3390/educsci15111537 | J17: Journal article (source list; verify) | L17: Journal Papers | M17: No | O17: Include | R17: Background | U17: Source-list summary (not verified against full text): Discusses moving from identifying AI-written work to designing authentic tasks. Useful for establishing why assessment redesign is preferable to detection alone. | W17: Imported from supplied paper list. Verify author(s), journal, year and DOI; retrieve full text, screen and extract supporting pages. No full-text review completed. 16/10/2026 relevance decision: Include. Addresses assessment design, verification of understanding, assessment validity or integrity in AI-rich education. Revised strict-scope decision: Background only. Broad AI, learning, literacy or policy context, or insufficient direct assessment-design evidence in the supplied summary; retain for background only. | AD17: =IF(G17="","",IF(F17="","",IF(AND(F17>=2022,F17<=2024),"Review 2026 applicability",""))) | AF17: =IF(G17="","",IF(I17="","",IF(COUNTIF($I$2:$I$100,I17)>1,"Check duplicate",""))) | AG17: =IF(G17="","",IF(M17="Yes","Duplicate",IF(OR(R17="",R17="Pending"),"Review pending",""))) | AL17: R96 | AX17: Background, outside main synthesis | AY17: Tighter relevance screen of supplied title, context and summary; not a new full-text assessment. | AZ17: Broad AI, learning, literacy or policy context, or insufficient direct assessment-design evidence in the supplied summary; retain for background only. | BA17: Not independently checked against original full text.
A18: R17 | B18: 14/10/2026 | C18: User paper list, item 2 | D18: Assessing students’ DRIVE: A framework to evaluate learning through interactions with generative AI Original file: Group folder (1).docx | F18: 2025 | G18: Assessing students’ DRIVE: A framework to evaluate learning through interactions with generative AI | I18: https://doi.org/10.1016/j.caeai.2025.100497 | J18: Journal article (source list; verify) | L18: Journal Papers | M18: No | O18: Include | R18: Background | U18: Source-list summary (not verified against full text): Proposes evaluating learning evidence from students’ interactions with GenAI. Useful for assessing the decisions and reasoning behind AI-supported submissions. | W18: Imported from supplied paper list. Verify author(s), journal, year and DOI; retrieve full text, screen and extract supporting pages. No full-text review completed. 16/10/2026 relevance decision: Include. Addresses assessment design, verification of understanding, assessment validity or integrity in AI-rich education. Revised strict-scope decision: Background only. Broad AI, learning, literacy or policy context, or insufficient direct assessment-design evidence in the supplied summary; retain for background only. | AD18: =IF(G18="","",IF(F18="","",IF(AND(F18>=2022,F18<=2024),"Review 2026 applicability",""))) | AF18: =IF(G18="","",IF(I18="","",IF(COUNTIF($I$2:$I$100,I18)>1,"Check duplicate",""))) | AG18: =IF(G18="","",IF(M18="Yes","Duplicate",IF(OR(R18="",R18="Pending"),"Review pending",""))) | AL18: R96 | AX18: Background, outside main synthesis | AY18: Tighter relevance screen of supplied title, context and summary; not a new full-text assessment. | AZ18: Broad AI, learning, literacy or policy context, or insufficient direct assessment-design evidence in the supplied summary; retain for background only. | BA18: Not independently checked against original full text.
A19: R18 | B19: 14/10/2026 | C19: User paper list, item 3 | D19: A scoping review on how generative artificial intelligence transforms assessment in higher education Original file: Group folder (1).docx | F19: 2024 | G19: A scoping review on how generative artificial intelligence transforms assessment in higher education | I19: https://doi.org/10.1186/s41239-024-00468-z | J19: Journal article (source list; verify) | L19: Journal Papers | M19: Yes | N19: R03 | O19: N/A | R19: Duplicate | U19: Source-list summary (not verified against full text): Maps existing research on how GenAI changes university assessment. Provides an evidence base for identifying assessment strategies and gaps. | W19: Duplicate DOI of R03. Imported from supplied list; existing record retained. | AD19: =IF(G19="","",IF(F19="","",IF(AND(F19>=2022,F19<=2024),"Review 2026 applicability",""))) | AF19: =IF(G19="","",IF(I19="","",IF(COUNTIF($I$2:$I$100,I19)>1,"Check duplicate",""))) | AG19: =IF(G19="","",IF(M19="Yes","Duplicate",IF(OR(R19="",R19="Pending"),"Review pending",""))) | AL19: R96
A20: R19 | B20: 14/10/2026 | C20: User paper list, item 4 | D20: Generative Artificial Intelligence in Tertiary Education: Assessment Redesign Principles and Considerations Original file: Relevant Papers 2022-26(1).docx | E20: Lye, C. Y.; Lim, L. | F20: 2024 | G20: Generative artificial intelligence in tertiary education: Assessment redesign principles and considerations | H20: Education Sciences, 14(6), Article 569 | I20: https://doi.org/10.3390/educsci14060569 | J20: Journal article | K20: Conceptual framework: Against, Avoid and Adopt (AAA); no experimental comparison | L20: Direct GenAI; cross-disciplinary tertiary assessment | M20: No | O20: Include | R20: Background | U20: Source-list summary (not verified against full text): Outlines principles for revising assessment in the presence of GenAI. Helps structure recommendations for AI-permitted assessment tasks. Summary supplied in 15.10.2026.pdf (not independently verified): GenAI creates opportunities for learning but also raises concerns about academic integrity, reliability and misinformation. ; AI-detection tools have limitations and may produce inaccurate results. ; Prohibiting GenAI across all assessments may not adequately prepare students for professional environments where AI is used. ; The AAA principle provides three broad approaches to assessment design: Against, Avoid and Adopt. ; Assessment decisions should reflect learning objectives and the purpose of each task rather than applying a single rule to every assessment. | W20: Imported from supplied paper list. Verify author(s), journal, year and DOI; retrieve full text, screen and extract supporting pages. No full-text review completed. Added detailed source summary from 15.10.2026.pdf, Paper 5. Verify against original article. Computing applications and RQ mapping are source interpretations. 16/10/2026 relevance decision: Include. Addresses assessment design, verification of understanding, assessment validity or integrity in AI-rich education. Revised strict-scope decision: Background only. Broad AI, learning, literacy or policy context, or insufficient direct assessment-design evidence in the supplied summary; retain for background only. | AD20: =IF(G20="","",IF(F20="","",IF(AND(F20>=2022,F20<=2024),"Review 2026 applicability",""))) | AF20: =IF(G20="","",IF(I20="","",IF(COUNTIF($I$2:$I$100,I20)>1,"Check duplicate",""))) | AG20: =IF(G20="","",IF(M20="Yes","Duplicate",IF(OR(R20="",R20="Pending"),"Review pending",""))) | AL20: R96 | AO20: Assessment redesign ; Transparent and responsible GenAI use ; Authentic assessment ; Academic integrity ; AI literacy development | AP20: Against: Assessments in which GenAI is not permitted because independent performance is essential. ; Avoid: Redesigning tasks to reduce reliance on activities that AI can complete without demonstrating the intended learning outcomes. ; Adopt: Assessments that deliberately incorporate GenAI and evaluate students' ability to use it appropriately. ; Transparent AI-use instructions ; Reflection on AI-assisted work ; Justification of technical decisions ; Practical demonstrations of individual competence | AQ20: Direct GenAI; cross-disciplinary tertiary assessment | AR20: This paper provides a useful conceptual framework for our project because it argues that restricting AI or attempting to detect AI-generated work is not sufficient to address the challenges of GenAI in education. Different assessments have different purposes. Some tasks may need to measure students' independent foundational knowledge, while others may benefit from allowing students to use AI as part of realistic professional practice. For computing education, this distinction is particularly important. Students may need to demonstrate unaided programming fundamentals in one assessment while using AI-assisted debugging or code generation in another. In both cases, assessment design should provide appropriate evidence of the intended learning outcomes. This aligns with our project objective of developing assessment strategies that balance responsible AI use with the verification of individual student achievement. | AS20: The paper is primarily conceptual and proposes a framework rather than experimentally comparing the effectiveness of different assessment strategies. The AAA principle provides guidance for categorising assessment approaches, but it does not establish that one category consistently produces more valid or reliable results than another. Furthermore, the framework does not independently verify whether students have achieved the intended learning outcomes. Practical tasks, oral explanations, process evidence and other assessment methods may still be needed to establish individual competence. | AU20: RQ1: Provides a framework for redesigning assessments to maintain appropriate evidence of individual student achievement when GenAI is available. RQ2: Identifies challenges associated with academic integrity, AI-generated misinformation and the limitations of AI-detection approaches. RQ4: Helps categorise assessment vulnerability according to whether AI use is prohibited, avoided through task redesign or deliberately incorporated. However, the paper does not experimentally measure vulnerability. RQ5: Supports a balanced approach to GenAI integration by matching assessment design to learning objectives and the intended role of AI. | AV20: The AAA framework helps our project categorise assessment strategies according to the role GenAI should play. For example, a closed-book programming test may restrict AI to assess foundational skills. A take-home software-design assignment may avoid tasks that AI can complete without meaningful student input, or it may explicitly permit AI and require students to evaluate and justify its outputs. This framework supports a balanced approach in which students' use of AI is determined by the assessment objectives and the evidence needed to establish competence. | AW20: Lye, C. Y., & Lim, L. (2024). Generative artificial intelligence in tertiary education: Assessment redesign principles and considerations. Education Sciences, 14(6), Article 569. https://doi.org/10.3390/educsci14060569 | AX20: Background, outside main synthesis | AY20: Tighter relevance screen of supplied title, context and summary; not a new full-text assessment. | AZ20: Broad AI, learning, literacy or policy context, or insufficient direct assessment-design evidence in the supplied summary; retain for background only. | BA20: Not independently checked against original full text.
A21: R20 | B21: 14/10/2026 | C21: User paper list, item 5 | D21: Reinventing assessments with ChatGPT and other online tools: Opportunities for GenAI-empowered assessment practices Original file: Relevant Papers 2022-26(1).docx | E21: Foung, D.; Lin, H. F.; Chen, S. W. J. | F21: 2024 | G21: Reinventing assessments with ChatGPT and other online tools: Opportunities for GenAI-empowered assessment practices | H21: Computers and Education: Artificial Intelligence, 6, Article 100250 | I21: https://doi.org/10.1016/j.caeai.2024.100250 | J21: Journal article | K21: Qualitative assessment redesign study: reflections from 74 students and focus groups with 28 students | L21: Direct GenAI; elective English course in Hong Kong | M21: No | O21: Include | R21: Background | U21: Source-list summary (not verified against full text): Examines assessment practices built around the use of GenAI and other digital tools. Offers ideas for evaluating learning when AI assistance is permitted. Summary supplied in 15.10.2026.pdf (not independently verified): The study analysed reflections from 74 students and interviews with 28 students. ; Students demonstrated the ability to select different online tools for different purposes. ; Allowing students to choose tools provided opportunities to develop evaluation and decision-making skills. ; Differences between free and premium tools raised concerns about equitable access. ; The findings support assessment practices that allow appropriate AI use while considering fairness and learning objectives. | W21: Imported from supplied paper list. Verify author(s), journal, year and DOI; retrieve full text, screen and extract supporting pages. No full-text review completed. Added detailed source summary from 15.10.2026.pdf, Paper 3. Verify against original article. Computing applications and RQ mapping are source interpretations. 16/10/2026 relevance decision: Include. Relevant conceptual, learning-process, AI-literacy or institutional context; use as supporting evidence, not proof of assessment effectiveness. Revised strict-scope decision: Background only. Broad AI, learning, literacy or policy context, or insufficient direct assessment-design evidence in the supplied summary; retain for background only. | AD21: =IF(G21="","",IF(F21="","",IF(AND(F21>=2022,F21<=2024),"Review 2026 applicability",""))) | AF21: =IF(G21="","",IF(I21="","",IF(COUNTIF($I$2:$I$100,I21)>1,"Check duplicate",""))) | AG21: =IF(G21="","",IF(M21="Yes","Duplicate",IF(OR(R21="",R21="Pending"),"Review pending",""))) | AL21: R96 | AO21: Transparent and responsible GenAI use ; Assessment redesign ; Reflective assessment ; AI literacy development ; Process-based assessment | AP21: Draft submissions and iterative improvements ; Reflection on AI tool usage ; Justification of tool selection ; Documentation of AI-generated suggestions ; Evaluation of AI-generated content ; Transparent disclosure of AI assistance | AQ21: Direct GenAI; elective English course in Hong Kong | AR21: This paper provides useful evidence for our project because it demonstrates how assessments can be redesigned to incorporate GenAI into learning activities. Instead of treating AI only as a threat to academic integrity, educators can create tasks that require students to select appropriate tools, evaluate AI-generated information and reflect on their decisions. For computing education, students could use AI to generate code, debug programs or explore alternative solutions. They could then explain which suggestions they accepted, modified or rejected and justify their decisions. This aligns with our project objective of developing assessment approaches that recognise the role of GenAI while providing stronger evidence of students' individual understanding and decision-making abilities. | AS21: The study focuses on an elective English course rather than computing education. Its findings therefore cannot automatically be generalised to programming, software engineering or cybersecurity assessments. The research uses qualitative evidence from student reflections and focus-group interviews. It does not experimentally establish whether the redesigned assessments improve academic integrity or reliably verify individual competence. Additionally, reflection and disclosure do not independently prove that a student understands the submitted work. These methods should be combined with practical demonstrations, oral explanations or individual problem-solving tasks. | AU21: RQ1: Supports assessment redesign that evaluates students' learning processes and decision- making alongside their final submissions. RQ2: Identifies challenges involving responsible AI use, tool selection and equitable access to AI technologies. RQ4: Highlights the need to move beyond final-output assessment, although the study does not directly measure the vulnerability of computing assessments to GenAI. RQ5: Supports integrating GenAI transparently into assessment while requiring students to evaluate tools, justify decisions and reflect on their learning. | AV21: The paper supports moving beyond assessments that evaluate only the final answer or submission. It suggests that students' tool-selection decisions and reflections can provide additional evidence of their learning. In computing education, this approach could be applied through programming tasks, debugging exercises and software-design problems. Students could submit their initial work, document AI assistance, explain changes made to their solutions and reflect on the accuracy of AI- generated suggestions. These practices may help educators evaluate both technical outcomes and individual reasoning in GenAI-supported learning environments. | AW21: Foung, D., Lin, H. F., & Chen, S. W. J. (2024). Reinventing assessments with ChatGPT and other online tools: Opportunities for GenAI-empowered assessment practices. Computers and Education: Artificial Intelligence, 6, Article 100250. https://doi.org/10.1016/j.caeai.2024.100250 | AX21: Background, outside main synthesis | AY21: Tighter relevance screen of supplied title, context and summary; not a new full-text assessment. | AZ21: Broad AI, learning, literacy or policy context, or insufficient direct assessment-design evidence in the supplied summary; retain for background only. | BA21: Not independently checked against original full text.
A22: R21 | B22: 14/10/2026 | C22: User paper list, item 6 | D22: Developing evaluative judgement for a time of generative artificial intelligence Original file: Relevant Papers 2022-26(1).docx | F22: 2024 | G22: Developing evaluative judgement for a time of generative artificial intelligence | I22: https://doi.org/10.1080/02602938.2024.2335321 | J22: Journal article (source list; verify) | L22: Journal Papers | M22: No | O22: Include | R22: Background | U22: Source-list summary (not verified against full text): Considers students’ ability to judge the quality of work in an AI-rich environment. Supports marking the evaluation and justification of AI outputs. | W22: Imported from supplied paper list. Verify author(s), journal, year and DOI; retrieve full text, screen and extract supporting pages. No full-text review completed. 16/10/2026 relevance decision: Include. Addresses assessment design, verification of understanding, assessment validity or integrity in AI-rich education. Revised strict-scope decision: Background only. Broad AI, learning, literacy or policy context, or insufficient direct assessment-design evidence in the supplied summary; retain for background only. | AD22: =IF(G22="","",IF(F22="","",IF(AND(F22>=2022,F22<=2024),"Review 2026 applicability",""))) | AF22: =IF(G22="","",IF(I22="","",IF(COUNTIF($I$2:$I$100,I22)>1,"Check duplicate",""))) | AG22: =IF(G22="","",IF(M22="Yes","Duplicate",IF(OR(R22="",R22="Pending"),"Review pending",""))) | AL22: R96 | AX22: Background, outside main synthesis | AY22: Tighter relevance screen of supplied title, context and summary; not a new full-text assessment. | AZ22: Broad AI, learning, literacy or policy context, or insufficient direct assessment-design evidence in the supplied summary; retain for background only. | BA22: Not independently checked against original full text.
A23: R22 | B23: 14/10/2026 | C23: User paper list, item 7 | D23: Guidelines for learning design and assessment for generative artificial intelligence-integrated education: a unified view Original file: Relevant Papers 2022-26(1).docx | F23: 2025 | G23: Guidelines for learning design and assessment for generative artificial intelligence-integrated education: a unified view | I23: https://doi.org/10.1108/ILS-11-2024-0148 | J23: Journal article (source list; verify) | L23: Journal Papers | M23: No | O23: Include | R23: Background | U23: Source-list summary (not verified against full text): Addresses teaching and assessment design where GenAI is integrated into learning. Provides principles that can inform a practical redesign framework. | W23: Imported from supplied paper list. Verify author(s), journal, year and DOI; retrieve full text, screen and extract supporting pages. No full-text review completed. 16/10/2026 relevance decision: Include. Addresses assessment design, verification of understanding, assessment validity or integrity in AI-rich education. Revised strict-scope decision: Background only. Broad AI, learning, literacy or policy context, or insufficient direct assessment-design evidence in the supplied summary; retain for background only. | AD23: =IF(G23="","",IF(F23="","",IF(AND(F23>=2022,F23<=2024),"Review 2026 applicability",""))) | AF23: =IF(G23="","",IF(I23="","",IF(COUNTIF($I$2:$I$100,I23)>1,"Check duplicate",""))) | AG23: =IF(G23="","",IF(M23="Yes","Duplicate",IF(OR(R23="",R23="Pending"),"Review pending",""))) | AL23: R96 | AX23: Background, outside main synthesis | AY23: Tighter relevance screen of supplied title, context and summary; not a new full-text assessment. | AZ23: Broad AI, learning, literacy or policy context, or insufficient direct assessment-design evidence in the supplied summary; retain for background only. | BA23: Not independently checked against original full text.
A24: R23 | B24: 14/10/2026 | C24: User paper list, item 8 | D24: Embracing a new world: authentic assessment designs in an age of generative artificial intelligence (GenAI) Original file: Relevant Papers 2022-26(1).docx | F24: 2026 | G24: Embracing a new world: authentic assessment designs in an age of generative artificial intelligence (GenAI) | I24: https://doi.org/10.1080/13603108.2025.2601741 | J24: Journal article (source list; verify) | L24: Journal Papers | M24: No | O24: Include | R24: Background | U24: Source-list summary (not verified against full text): Explores authentic assessment design in the GenAI era. Helps connect assessment tasks to demonstrable personal competence. | W24: Imported from supplied paper list. Verify author(s), journal, year and DOI; retrieve full text, screen and extract supporting pages. No full-text review completed. 16/10/2026 relevance decision: Include. Addresses assessment design, verification of understanding, assessment validity or integrity in AI-rich education. Revised strict-scope decision: Background only. Broad AI, learning, literacy or policy context, or insufficient direct assessment-design evidence in the supplied summary; retain for background only. | AD24: =IF(G24="","",IF(F24="","",IF(AND(F24>=2022,F24<=2024),"Review 2026 applicability",""))) | AF24: =IF(G24="","",IF(I24="","",IF(COUNTIF($I$2:$I$100,I24)>1,"Check duplicate",""))) | AG24: =IF(G24="","",IF(M24="Yes","Duplicate",IF(OR(R24="",R24="Pending"),"Review pending",""))) | AL24: R96 | AX24: Background, outside main synthesis | AY24: Tighter relevance screen of supplied title, context and summary; not a new full-text assessment. | AZ24: Broad AI, learning, literacy or policy context, or insufficient direct assessment-design evidence in the supplied summary; retain for background only. | BA24: Not independently checked against original full text.
A25: R24 | B25: 14/10/2026 | C25: User paper list, item 9 | D25: Changing EAP assessment practices in the age of generative artificial intelligence: The case of Scottish higher education institutions Original file: Relevant Papers 2022-26(1).docx | F25: 2026 | G25: Changing EAP assessment practices in the age of generative artificial intelligence: The case of Scottish higher education institutions | I25: https://doi.org/10.1016/j.jeap.2025.101609 | J25: Journal article (source list; verify) | L25: Journal Papers | M25: No | O25: Include | R25: Background | U25: Source-list summary (not verified against full text): Examines how English for Academic Purposes assessment practices respond to GenAI. Offers cross-disciplinary examples of assessment change. | W25: Imported from supplied paper list. Verify author(s), journal, year and DOI; retrieve full text, screen and extract supporting pages. No full-text review completed. 16/10/2026 relevance decision: Include. Relevant conceptual, learning-process, AI-literacy or institutional context; use as supporting evidence, not proof of assessment effectiveness. Revised strict-scope decision: Background only. Other-discipline educational evidence; potentially transferable background, outside the Computing/IT assessment sample. | AD25: =IF(G25="","",IF(F25="","",IF(AND(F25>=2022,F25<=2024),"Review 2026 applicability",""))) | AF25: =IF(G25="","",IF(I25="","",IF(COUNTIF($I$2:$I$100,I25)>1,"Check duplicate",""))) | AG25: =IF(G25="","",IF(M25="Yes","Duplicate",IF(OR(R25="",R25="Pending"),"Review pending",""))) | AL25: R96 | AX25: Background, outside main synthesis | AY25: Tighter relevance screen of supplied title, context and summary; not a new full-text assessment. | AZ25: Other-discipline educational evidence; potentially transferable background, outside the Computing/IT assessment sample. | BA25: Not independently checked against original full text.
A26: R25 | B26: 14/10/2026 | C26: User paper list, item 10 | D26: Online assessment in the age of artificial intelligence Original file: Relevant Papers 2022-26(1).docx | F26: 2024 | G26: Online assessment in the age of artificial intelligence | I26: https://doi.org/10.1007/s44217-024-00212-9 | J26: Journal article (source list; verify) | L26: Journal Papers | M26: No | O26: Include | R26: Background | U26: Source-list summary (not verified against full text): Discusses challenges posed by AI to online assessment. Relevant to designing unsupervised activities that generate stronger learning evidence. | W26: Imported from supplied paper list. Verify author(s), journal, year and DOI; retrieve full text, screen and extract supporting pages. No full-text review completed. 16/10/2026 relevance decision: Include. Addresses assessment design, verification of understanding, assessment validity or integrity in AI-rich education. Revised strict-scope decision: Background only. Broad AI, learning, literacy or policy context, or insufficient direct assessment-design evidence in the supplied summary; retain for background only. | AD26: =IF(G26="","",IF(F26="","",IF(AND(F26>=2022,F26<=2024),"Review 2026 applicability",""))) | AF26: =IF(G26="","",IF(I26="","",IF(COUNTIF($I$2:$I$100,I26)>1,"Check duplicate",""))) | AG26: =IF(G26="","",IF(M26="Yes","Duplicate",IF(OR(R26="",R26="Pending"),"Review pending",""))) | AL26: R96 | AX26: Background, outside main synthesis | AY26: Tighter relevance screen of supplied title, context and summary; not a new full-text assessment. | AZ26: Broad AI, learning, literacy or policy context, or insufficient direct assessment-design evidence in the supplied summary; retain for background only. | BA26: Not independently checked against original full text.
A27: R26 | B27: 14/10/2026 | C27: User paper list, item 11 | D27: Is AI changing learning and assessment as we know it? Evidence from a ChatGPT experiment and a conceptual framework Original file: Relevant Papers 2022-26(1).docx | F27: 2024 | G27: Is AI changing learning and assessment as we know it? Evidence from a ChatGPT experiment and a conceptual framework | I27: https://doi.org/10.1016/j.heliyon.2024.e25953 | J27: Journal article (source list; verify) | L27: Journal Papers | M27: No | O27: Include | R27: Background | U27: Source-list summary (not verified against full text): Uses evidence from a ChatGPT-related experiment to examine learning and assessment. Provides a conceptual basis for thinking about AI’s influence on results. | W27: Imported from supplied paper list. Verify author(s), journal, year and DOI; retrieve full text, screen and extract supporting pages. No full-text review completed. 16/10/2026 relevance decision: Include. Relevant conceptual, learning-process, AI-literacy or institutional context; use as supporting evidence, not proof of assessment effectiveness. Revised strict-scope decision: Background only. Broad AI, learning, literacy or policy context, or insufficient direct assessment-design evidence in the supplied summary; retain for background only. | AD27: =IF(G27="","",IF(F27="","",IF(AND(F27>=2022,F27<=2024),"Review 2026 applicability",""))) | AF27: =IF(G27="","",IF(I27="","",IF(COUNTIF($I$2:$I$100,I27)>1,"Check duplicate",""))) | AG27: =IF(G27="","",IF(M27="Yes","Duplicate",IF(OR(R27="",R27="Pending"),"Review pending",""))) | AL27: R96 | AX27: Background, outside main synthesis | AY27: Tighter relevance screen of supplied title, context and summary; not a new full-text assessment. | AZ27: Broad AI, learning, literacy or policy context, or insufficient direct assessment-design evidence in the supplied summary; retain for background only. | BA27: Not independently checked against original full text.
